{
 "cells": [
  {
   "cell_type": "code",
   "execution_count": 1,
   "metadata": {},
   "outputs": [],
   "source": [
    "from langchain_community.embeddings.fastembed import FastEmbedEmbeddings"
   ]
  },
  {
   "cell_type": "code",
   "execution_count": 2,
   "metadata": {},
   "outputs": [
    {
     "name": "stderr",
     "output_type": "stream",
     "text": [
      "c:\\Users\\AMONTORIOP002\\Desktop\\DEVOPS\\gcp_aiaas\\.venv\\Lib\\site-packages\\tqdm\\auto.py:21: TqdmWarning: IProgress not found. Please update jupyter and ipywidgets. See https://ipywidgets.readthedocs.io/en/stable/user_install.html\n",
      "  from .autonotebook import tqdm as notebook_tqdm\n",
      "\u001b[32m2024-12-16 15:43:39.388\u001b[0m | \u001b[31m\u001b[1mERROR   \u001b[0m | \u001b[36mfastembed.common.model_management\u001b[0m:\u001b[36mdownload_model\u001b[0m:\u001b[36m250\u001b[0m - \u001b[31m\u001b[1mCould not download model from HuggingFace: (MaxRetryError(\"HTTPSConnectionPool(host='huggingface.co', port=443): Max retries exceeded with url: /api/models/qdrant/bge-small-en-v1.5-onnx-q/revision/main (Caused by SSLError(SSLCertVerificationError(1, '[SSL: CERTIFICATE_VERIFY_FAILED] certificate verify failed: self-signed certificate in certificate chain (_ssl.c:1006)')))\"), '(Request ID: 678cf948-49eb-4361-9c27-bdd88bc61d58)')Falling back to other sources.\u001b[0m\n"
     ]
    },
    {
     "ename": "ValidationError",
     "evalue": "1 validation error for FastEmbedEmbeddings\n__root__\n  Could not download model BAAI/bge-small-en-v1.5 from any source. (type=value_error)",
     "output_type": "error",
     "traceback": [
      "\u001b[1;31m---------------------------------------------------------------------------\u001b[0m",
      "\u001b[1;31mValidationError\u001b[0m                           Traceback (most recent call last)",
      "Cell \u001b[1;32mIn[2], line 1\u001b[0m\n\u001b[1;32m----> 1\u001b[0m embeddings \u001b[38;5;241m=\u001b[39m \u001b[43mFastEmbedEmbeddings\u001b[49m\u001b[43m(\u001b[49m\u001b[43m)\u001b[49m\n",
      "File \u001b[1;32mc:\\Users\\AMONTORIOP002\\Desktop\\DEVOPS\\gcp_aiaas\\.venv\\Lib\\site-packages\\pydantic\\v1\\main.py:341\u001b[0m, in \u001b[0;36mBaseModel.__init__\u001b[1;34m(__pydantic_self__, **data)\u001b[0m\n\u001b[0;32m    339\u001b[0m values, fields_set, validation_error \u001b[38;5;241m=\u001b[39m validate_model(__pydantic_self__\u001b[38;5;241m.\u001b[39m\u001b[38;5;18m__class__\u001b[39m, data)\n\u001b[0;32m    340\u001b[0m \u001b[38;5;28;01mif\u001b[39;00m validation_error:\n\u001b[1;32m--> 341\u001b[0m     \u001b[38;5;28;01mraise\u001b[39;00m validation_error\n\u001b[0;32m    342\u001b[0m \u001b[38;5;28;01mtry\u001b[39;00m:\n\u001b[0;32m    343\u001b[0m     object_setattr(__pydantic_self__, \u001b[38;5;124m'\u001b[39m\u001b[38;5;124m__dict__\u001b[39m\u001b[38;5;124m'\u001b[39m, values)\n",
      "\u001b[1;31mValidationError\u001b[0m: 1 validation error for FastEmbedEmbeddings\n__root__\n  Could not download model BAAI/bge-small-en-v1.5 from any source. (type=value_error)"
     ]
    }
   ],
   "source": [
    "embeddings = FastEmbedEmbeddings()"
   ]
  }
 ],
 "metadata": {
  "kernelspec": {
   "display_name": ".venv",
   "language": "python",
   "name": "python3"
  },
  "language_info": {
   "codemirror_mode": {
    "name": "ipython",
    "version": 3
   },
   "file_extension": ".py",
   "mimetype": "text/x-python",
   "name": "python",
   "nbconvert_exporter": "python",
   "pygments_lexer": "ipython3",
   "version": "3.11.5"
  }
 },
 "nbformat": 4,
 "nbformat_minor": 2
}
